Workbook

Sheet 🐛 Bug & Issue Log
A1: 🐛 BoldBox UAT — Bug & Issue Log
A2: Last Updated: 14 Jun 2026 | App: BoldBox Early Access | Platform: Android (Google Play)
A3: Issue ID | B3: Date Found | C3: Found By | D3: Screen / Feature | E3: Severity | F3: Type | G3: Description | H3: Steps to Reproduce | I3: Expected Result | J3: Actual Result | K3: Device | L3: OS Version | M3: App Version | N3: Screenshot / Video | O3: Status | P3: Assigned To | Q3: Fix Version | R3: Date Fixed | S3: Notes | U3: SEVERITY GUIDE
A4: BUG-001 | B4: 14 Jun 2026 | C4: Mighty | D4: Video Player | E4: P1 — Critical | F4: Crash | G4: กดปุ่ม Play แล้วแอพ crash กลับ Home Screen ทันที | H4: 1. เปิดแอพ 2. แตะซีรีส์ใดก็ได้ 3. กดปุ่ม Play | I4: วิดีโอเล่นได้ปกติ | J4: แอพ crash กลับ Home Screen | K4: Samsung Galaxy S23 | L4: Android 14 | M4: v0.1.0 (build 1) | N4: - | O4: Open | P4: Joe | S4: เกิดทุกครั้ง ทุกเครื่องที่ทดสอบ | U4: P1 — Critical | V4: Crash / ฟีเจอร์หลักใช้ไม่ได้ → Fix ภายใน 24 ชม.
A5: BUG-002 | B5: 14 Jun 2026 | C5: Mighty | D5: Login / Sign Up | E5: P1 — Critical | F5: Bug | G5: Sign Up ด้วย Email แล้ว Error 500 ไม่สามารถสมัครได้ | H5: 1. กด Sign Up 2. กรอก Email + Password 3. กด Submit | I5: สมัครสำเร็จ → เข้าสู่ For You Feed | J5: Error 500 — Internal Server Error | K5: Pixel 7 | L5: Android 13 | M5: v0.1.0 (build 1) | N5: - | O5: Open | P5: Joe | S5: ทดสอบด้วย Gmail และ Hotmail ทั้งคู่ Error | U5: P2 — High | V5: ฟีเจอร์ผิดพลาด แต่ยังใช้ได้ → Fix ภายใน 3 วัน
A6: BUG-003 | B6: 14 Jun 2026 | C6: Ake | D6: For You Feed | E6: P2 — High | F6: UI | G6: For You Banner Ad ไม่แสดงผล — พื้นที่โฆษณาว่างเปล่า | H6: 1. Login สำเร็จ 2. ดู For You Feed 3. Scroll ดูพื้นที่ Banner | I6: แสดง Banner Ad ของแบรนด์ | J6: พื้นที่ว่าง ไม่มีโฆษณาขึ้น | K6: Samsung Galaxy A54 | L6: Android 13 | M6: v0.1.0 (build 1) | N6: - | O6: Open | P6: Joe | U6: P3 — Medium | V6: UI/UX ผิดพลาด → Fix ใน Sprint ถัดไป
A7: BUG-004 | B7: 14 Jun 2026 | C7: Mighty | D7: IAP / Payment | E7: P1 — Critical | F7: Bug | G7: ซื้อ Ad-Free Package ฿49 ผ่าน Omise แล้ว Payment ไม่สำเร็จ | H7: 1. ไปที่ Settings 2. เลือก Ad-Free Package 3. กรอกบัตรเครดิต 4. กด Pay | I7: Payment สำเร็จ → ได้รับสิทธิ์ Ad-Free | J7: Error: Payment Failed — กลับมาหน้าเดิม | K7: iPhone SE (Test Android APK) | L7: Android 12 | M7: v0.1.0 (build 1) | N7: - | O7: Open | P7: Joe | S7: ทดสอบบัตร Test Card ของ Omise | U7: P4 — Low | V7: Cosmetic / Nice-to-have → Backlog
A8: BUG-005 | B8: 14 Jun 2026 | C8: Fim | D8: Video Player | E8: P3 — Medium | F8: UI | G8: ปุ่ม Episode ถัดไปชนขอบจอบน Android หน้าจอ 6.1 นิ้ว | H8: 1. เปิดวิดีโอ 2. ดูปุ่ม Episode ถัดไปที่มุมขวาล่าง | I8: ปุ่มอยู่ใน safe area ชัดเจน | J8: ปุ่มถูก Navigation Bar บังครึ่งนึง | K8: Xiaomi 13T | L8: Android 14 | M8: v0.1.0 (build 1) | N8: - | O8: Open | P8: Joe | S8: เฉพาะ Gesture Navigation Mode | U8: STATUS GUIDE
A9: BUG-006 | U9: Open | V9: เจอแล้ว รอ assign
A10: BUG-007 | U10: In Progress | V10: Dev กำลังแก้
A11: BUG-008 | U11: Fixed | V11: แก้แล้ว รอ Verify
A12: BUG-009 | U12: Verified | V12: ทดสอบซ้ำผ่านแล้ว ปิด
A13: BUG-010 | U13: Won't Fix | V13: ตัดสินใจไม่แก้ (เหตุผลใน Notes)
A14: BUG-011
A15: BUG-012
A16: BUG-013
A17: BUG-014
A18: BUG-015
A19: BUG-016
A20: BUG-017
A21: BUG-018
A22: BUG-019
A23: BUG-020
A24: BUG-021
A25: BUG-022
... A59: BUG-056

Sheet ✅ Test Case Checklist
A1: ✅ BoldBox UAT — Test Case Checklist
A2: Tester: _______________ Round: ___ Date: 14 Jun 2026 App Version: v___
A3: # | B3: Test Area | C3: Test Case | D3: Pass ✅ / Fail ❌ / N/A | E3: Issue ID (ถ้า Fail) | F3: Notes / Observation | G3: Tester
A4: ONBOARDING
A5: 1 | B5: Splash & Loading | C5: เปิดแอพครั้งแรก → Splash Screen BoldBox แสดง + Loading เสร็จภายใน 3 วิ
A6: 2 | B6: Sign Up | C6: Sign Up ด้วย Email + Password → สมัครสำเร็จ เข้า Feed ได้
A7: 3 | B7: Login | C7: Login ด้วย Email ที่สมัครไว้ → เข้าได้ปกติ
A8: 4 | B8: Login — Wrong Password | C8: ใส่ Password ผิด → แสดง Error Message ชัดเจน
A9: 5 | B9: Forgot Password | C9: กด Forgot Password → รับ Email Reset ได้
A10: 6 | B10: Logout | C10: กด Logout → กลับสู่หน้า Login
A11: FOR YOU FEED
A12: 7 | B12: Feed Load | C12: เปิดแอพ → For You Feed โหลดซีรีส์ได้ภายใน 3 วิ
A13: 8 | B13: Scroll & Load More | C13: Scroll ลงไปเรื่อยๆ → โหลด Content เพิ่มอัตโนมัติ
A14: 9 | B14: Series Thumbnail | C14: Thumbnail ของซีรีส์ทุกเรื่องแสดงชัดเจน ไม่ blur
A15: 10 | B15: Tap Series → Detail | C15: แตะซีรีส์ → เปิดหน้า Series Detail ได้ถูกต้อง
A16: 11 | B16: For You Banner Ad | C16: Banner Ad แสดงในตำแหน่งที่กำหนด (ไม่ทับ content)
A17: 12 | B17: For You Box Ad | C17: Box Ad แสดงใน Feed ถูกตำแหน่ง
A18: 13 | B18: Genre Filter | C18: กด Filter ตาม Genre → แสดงเฉพาะ Genre นั้น
A19: SERIES DETAIL PAGE
A20: 14 | B20: Synopsis | C20: หน้า Detail แสดง Synopsis, Genre, จำนวน Episode ถูกต้อง
A21: 15 | B21: Episode List | C21: รายการ Episode ทุก ep แสดงครบถ้วน
A22: 16 | B22: Add to Favorites | C22: กด Favorite → เพิ่มใน Favorites List สำเร็จ
A23: VIDEO PLAYER
A24: 17 | B24: Play Video | C24: กด Play → วิดีโอเล่นได้ภายใน 2 วิ ไม่ Crash
A25: 18 | B25: Pause / Resume | C25: กด Pause แล้ว Resume → เล่นต่อจากจุดเดิม
A26: 19 | B26: Seek Bar | C26: ลาก Seek Bar ไปจุดอื่น → กระโดดไปตำแหน่งนั้นถูกต้อง
A27: 20 | B27: Auto Next Episode | C27: จบ Episode → ขึ้น Episode ถัดไปอัตโนมัติ
A28: 21 | B28: Play Screen Banner Ad | C28: Banner Ad แสดงบน Play Screen (non-VIP)
A29: 22 | B29: Play Screen Box Ad | C29: Box Ad แสดงบน Play Screen (non-VIP)
A30: 23 | B30: Background → Resume | C30: กด Home แล้วกลับมา → เล่นต่อจากจุดที่ค้างไว้
A31: 24 | B31: Landscape Mode | C31: หมุนจอ → Player ปรับ Landscape ได้ถูกต้อง
A32: IAP — AD-FREE PACKAGE
A33: 25 | B33: Purchase Flow | C33: กด Ad-Free ฿49 → หน้า Payment แสดงถูกต้อง
A34: 26 | B34: Payment Success | C34: ชำระเงินผ่าน Omise สำเร็จ → ได้รับสิทธิ์ Ad-Free ทันที
A35: 27 | B35: Ad Hidden After Purchase | C35: หลังซื้อ → Banner และ Box Ad บน Play Screen หายไป
A36: 28 | B36: Persistent After Restart | C36: ปิดแอพแล้วเปิดใหม่ → สิทธิ์ Ad-Free ยังอยู่
A37: 29 | B37: Payment Failed | C37: ใช้บัตรทดสอบที่ Fail → แสดง Error Message ชัดเจน
A38: VIP SUBSCRIPTION
A39: 30 | B39: Subscribe Flow | C39: กด VIP ฿129/เดือน → หน้า Payment ถูกต้อง
A40: 31 | B40: Payment Success | C40: ชำระ VIP สำเร็จ → ได้รับ Badge + สิทธิ์ครบ
...

Sheet 📊 Summary Dashboard
A1: 📊 BoldBox UAT — Summary Dashboard
A2: Auto-calculated from Bug & Issue Log | Last Updated: 14 Jun 2026
A4: 📌 ISSUE OVERVIEW
B5: Total Issues Logged | C5: =COUNTA('🐛 Bug & Issue Log'!A4:A200) -> 56
B6: Open | C6: =COUNTIF('🐛 Bug & Issue Log'!O4:O200,"Open") -> 5
B7: In Progress | C7: =COUNTIF('🐛 Bug & Issue Log'!O4:O200,"In Progress") -> 0
B8: Fixed (รอ Verify) | C8: =COUNTIF('🐛 Bug & Issue Log'!O4:O200,"Fixed") -> 0
B9: Verified ✅ (ปิดแล้ว) | C9: =COUNTIF('🐛 Bug & Issue Log'!O4:O200,"Verified") -> 0
B10: Won't Fix | C10: =COUNTIF('🐛 Bug & Issue Log'!O4:O200,"Won't Fix") -> 0
A12: 🔴 ISSUES BY SEVERITY
B13: P1 — Critical | C13: =COUNTIF('🐛 Bug & Issue Log'!E4:E200,"P1 — Critical") -> 3
B14: P2 — High | C14: =COUNTIF('🐛 Bug & Issue Log'!E4:E200,"P2 — High") -> 1
B15: P3 — Medium | C15: =COUNTIF('🐛 Bug & Issue Log'!E4:E200,"P3 — Medium") -> 1
B16: P4 — Low | C16: =COUNTIF('🐛 Bug & Issue Log'!E4:E200,"P4 — Low") -> 0
A18: 📱 ISSUES BY FEATURE AREA
B19: Video Player | C19: =COUNTIF('🐛 Bug & Issue Log'!D4:D200,"*Video Player*") -> 2
B20: Login / Sign Up | C20: =COUNTIF('🐛 Bug & Issue Log'!D4:D200,"*Login / Sign Up*") -> 1
B21: For You Feed | C21: =COUNTIF('🐛 Bug & Issue Log'!D4:D200,"*For You Feed*") -> 1
B22: IAP / Payment | C22: =COUNTIF('🐛 Bug & Issue Log'!D4:D200,"*IAP / Payment*") -> 1
B23: VIP Subscription | C23: =COUNTIF('🐛 Bug & Issue Log'!D4:D200,"*VIP Subscription*") -> 0
B24: Search | C24: =COUNTIF('🐛 Bug & Issue Log'!D4:D200,"*Search*") -> 0
B25: Profile / Settings | C25: =COUNTIF('🐛 Bug & Issue Log'!D4:D200,"*Profile / Settings*") -> 0
B26: Performance | C26: =COUNTIF('🐛 Bug & Issue Log'!D4:D200,"*Performance*") -> 0
A28: ✅ TEST COVERAGE
B29: Total Test Cases | C29: =48 -> 48
B30: Pass ✅ | C30: =COUNTIF('✅ Test Case Checklist'!D4:D200,"Pass ✅") -> 0
B31: Fail ❌ | C31: =COUNTIF('✅ Test Case Checklist'!D4:D200,"Fail ❌") -> 0
B32: N/A | C32: =COUNTIF('✅ Test Case Checklist'!D4:D200,"N/A") -> 0
B33: Not Tested Yet | C33: =48-COUNTIF('✅ Test Case Checklist'!D4:D200,"Pass ✅")-COUNTIF('✅ Test Case Checklist'!D4:D200,"Fail ❌")-COUNTIF('✅ Test Case Checklist'!D4:D200,"N/A") -> 48
B34: Coverage % | C34: =IFERROR(TEXT(COUNTIF('✅ Test Case Checklist'!D4:D200,"Pass ✅")/48,"0.0%"),"0.0%") -> 0.0%
A36: 📋 TESTING INFO
B37: App Name | C37: BoldBox — Micro Drama Streaming
B38: Platform | C38: Android (Google Play Early Access)
B39: App Version | C39: v0.1.0 (build 1)
B40: Testing Round | C40: Round 1
B41: Test Period | C41: 14 Jun 2026 — ongoing
B42: Lead Tester | C42: Mighty (CEO)
B43: Dev Lead | C43: Joe (CTO)
